<?xml version="1.0" ?>

<robot name="mini">


    <material name="white">
        <color rgba="1 1 1 1"/>
    </material>

    <material name="red">
        <color rgba="1 0 0 1"/>
    </material>

    <link name="base_link">
        <visual>
          <origin rpy="0 0 0" xyz="0 0 0.015" />
          <geometry>
            <cylinder radius="0.09" length="0.03" />
          </geometry>

        <material name="white"/>
        </visual>

        <collision>
            <origin rpy="0 0 0" xyz="0 0 0.015" />
          <geometry>
            <cylinder radius="0.09" length="0.03" />
          </geometry>
          </collision>
 
    </link>

    <joint name="base_link__link_01" type="revolute">
        <axis xyz="0 0 1"/>
        <limit effort="1000.0" lower="-3.14" upper="3.14" velocity="0.5"/>
        <origin rpy="1.57 0 0" xyz="0 0 0.03"/>
        <parent link="base_link"/>
        <child link="link_01"/>
        
    </joint>

    <link name="link_01">
        <visual>
            <origin rpy="1.57 0 0" xyz="0 0.096 0" />
            <geometry>
                <cylinder radius="0.02" length="0.192" />
            </geometry>
            <material name="white"/>
                
        </visual>

        <collision>
            <origin rpy="0 0 0" xyz="0 0 0.096" />
            <geometry>
                <cylinder radius="0.02" length="0.192" />
            </geometry>
          </collision>

 
    </link>


</robot>
